<sdf version='1.6'>
  <model name='minitaur'>
    <link name='base_link'>
      <pose frame=''>0 0 0 0 -0 0</pose>
      <inertial>
        <pose frame=''>0.083033 -0.15433 0.10624 0 -0 0</pose>
        <mass>0.71915</mass>
        <inertia>
          <ixx>0.0023612</ixx>
          <ixy>0</ixy>
          <ixz>6.8894e-06</ixz>
          <iyy>0.0062972</iyy>
          <iyz>0</iyz>
          <izz>0.0040109</izz>
        </inertia>
      </inertial>
      <collision name='base_link_collision'>
        <pose frame=''>0 0 0 0 -0 0</pose>
        <geometry>
          <mesh>
            <scale>1 1 1</scale>
            <uri>model://minitaur/meshes/base_link.STL</uri>
          </mesh>
        </geometry>
      </collision>
      <visual name='base_link_visual'>
        <pose frame=''>0 0 0 0 -0 0</pose>
        <geometry>
          <mesh>
            <scale>1 1 1</scale>
            <uri>model://minitaur/meshes/base_link.STL</uri>
          </mesh>
        </geometry>
      </visual>
    </link>
    <link name='leg1a1'>
      <pose frame=''>0.17303 -0.071332 0.10916 -1.5708 0 0</pose>
      <inertial>
        <pose frame=''>0.027399 0 -0.008649 0 -0 0</pose>
        <mass>0.0096655</mass>
        <inertia>
          <ixx>3.47e-07</ixx>
          <ixy>0</ixy>
          <ixz>7.67e-08</ixz>
          <iyy>3.57e-06</iyy>
          <iyz>0</iyz>
          <izz>3.82e-06</izz>
        </inertia>
      </inertial>
      <collision name='leg1a1_collision'>
        <pose frame=''>0 0 0 0 -0 0</pose>
        <geometry>
          <mesh>
            <scale>1 1 1</scale>
            <uri>model://minitaur/meshes/leg1a1.STL</uri>
          </mesh>
        </geometry>
      </collision>
      <visual name='leg1a1_visual'>
        <pose frame=''>0 0 0 0 -0 0</pose>
        <geometry>
          <mesh>
            <scale>1 1 1</scale>
            <uri>model://minitaur/meshes/leg1a1.STL</uri>
          </mesh>
        </geometry>
      </visual>
    </link>
    <joint name='leg1j1' type='revolute'>
      <child>leg1a1</child>
      <parent>base_link</parent>
      <axis>
        <xyz>0 -1 4e-06</xyz>
        <limit>
          <lower>-1e+16</lower>
          <upper>1e+16</upper>
        </limit>
        <dynamics>
          <spring_reference>0</spring_reference>
          <spring_stiffness>0</spring_stiffness>
        </dynamics>
        <use_parent_model_frame>1</use_parent_model_frame>
      </axis>
    </joint>
    <link name='leg1a2'>
      <pose frame=''>0.22303 -0.071332 0.10916 -1.5708 -0.89566 5e-06</pose>
      <inertial>
        <pose frame=''>-0.053394 -0 -0.002796 0 -0 0</pose>
        <mass>0.016662</mass>
        <inertia>
          <ixx>6.06e-07</ixx>
          <ixy>0</ixy>
          <ixz>-1.58e-07</ixz>
          <iyy>1.85e-05</iyy>
          <iyz>0</iyz>
          <izz>1.9e-05</izz>
        </inertia>
      </inertial>
      <collision name='leg1a2_collision'>
        <pose frame=''>0 0 0 0 -0 0</pose>
        <geometry>
          <mesh>
            <scale>1 1 1</scale>
            <uri>model://minitaur/meshes/leg1a2.STL</uri>
          </mesh>
        </geometry>
      </collision>
      <visual name='leg1a2_visual'>
        <pose frame=''>0 0 0 0 -0 0</pose>
        <geometry>
          <mesh>
            <scale>1 1 1</scale>
            <uri>model://minitaur/meshes/leg1a2.STL</uri>
          </mesh>
        </geometry>
      </visual>
    </link>
    <joint name='leg1j2' type='revolute'>
      <child>leg1a2</child>
      <parent>leg1a1</parent>
      <axis>
        <xyz>0 -1 4e-06</xyz>
        <limit>
          <lower>-1e+16</lower>
          <upper>1e+16</upper>
        </limit>
        <dynamics>
          <spring_reference>0</spring_reference>
          <spring_stiffness>0</spring_stiffness>
        </dynamics>
        <use_parent_model_frame>1</use_parent_model_frame>
      </axis>
    </joint>
    <link name='leg1a3'>
      <pose frame=''>0.14803 -0.065332 0.10916 1.5708 -0 -3.14159</pose>
      <inertial>
        <pose frame=''>0.027399 -0 -0.008649 0 -0 0</pose>
        <mass>0.0096655</mass>
        <inertia>
          <ixx>3.47e-07</ixx>
          <ixy>0</ixy>
          <ixz>7.67e-08</ixz>
          <iyy>3.57e-06</iyy>
          <iyz>0</iyz>
          <izz>3.82e-06</izz>
        </inertia>
      </inertial>
      <collision name='leg1a3_collision'>
        <pose frame=''>0 0 0 0 -0 0</pose>
        <geometry>
          <mesh>
            <scale>1 1 1</scale>
            <uri>model://minitaur/meshes/leg1a3.STL</uri>
          </mesh>
        </geometry>
      </collision>
      <visual name='leg1a3_visual'>
        <pose frame=''>0 0 0 0 -0 0</pose>
        <geometry>
          <mesh>
            <scale>1 1 1</scale>
            <uri>model://minitaur/meshes/leg1a3.STL</uri>
          </mesh>
        </geometry>
      </visual>
    </link>
    <joint name='leg1j3' type='revolute'>
      <child>leg1a3</child>
      <parent>base_link</parent>
      <axis>
        <xyz>7e-06 -1 4e-06</xyz>
        <limit>
          <lower>-1e+16</lower>
          <upper>1e+16</upper>
        </limit>
        <dynamics>
          <spring_reference>0</spring_reference>
          <spring_stiffness>0</spring_stiffness>
        </dynamics>
        <use_parent_model_frame>1</use_parent_model_frame>
      </axis>
    </joint>
    <link name='leg1a4'>
      <pose frame=''>0.09803 -0.065332 0.10916 1.5708 0.895693 3e-06</pose>
      <inertial>
        <pose frame=''>0.05 0 0.003 0 -0 0</pose>
        <mass>0.015531</mass>
        <inertia>
          <ixx>5.76e-07</ixx>
          <ixy>0</ixy>
          <ixz>0</ixz>
          <iyy>1.59e-05</iyy>
          <iyz>0</iyz>
          <izz>1.64e-05</izz>
        </inertia>
      </inertial>
      <collision name='leg1a4_collision'>
        <pose frame=''>0 0 0 0 -0 0</pose>
        <geometry>
          <mesh>
            <scale>1 1 1</scale>
            <uri>model://minitaur/meshes/leg1a4.STL</uri>
          </mesh>
        </geometry>
      </collision>
      <visual name='leg1a4_visual'>
        <pose frame=''>0 0 0 0 -0 0</pose>
        <geometry>
          <mesh>
            <scale>1 1 1</scale>
            <uri>model://minitaur/meshes/leg1a4.STL</uri>
          </mesh>
        </geometry>
      </visual>
    </link>
    <joint name='leg1j4' type='revolute'>
      <child>leg1a4</child>
      <parent>leg1a3</parent>
      <axis>
        <xyz>2e-06 -1 -1e-06</xyz>
        <limit>
          <lower>-1e+16</lower>
          <upper>1e+16</upper>
        </limit>
        <dynamics>
          <spring_reference>0</spring_reference>
          <spring_stiffness>0</spring_stiffness>
        </dynamics>
        <use_parent_model_frame>1</use_parent_model_frame>
      </axis>
    </joint>
    <link name='leg2a1'>
      <pose frame=''>0.018033 -0.071332 0.10916 -1.5708 0 0</pose>
      <inertial>
        <pose frame=''>0.027399 -0 -0.008649 0 -0 0</pose>
        <mass>0.0096655</mass>
        <inertia>
          <ixx>3.47e-07</ixx>
          <ixy>0</ixy>
          <ixz>7.67e-08</ixz>
          <iyy>3.57e-06</iyy>
          <iyz>0</iyz>
          <izz>3.82e-06</izz>
        </inertia>
      </inertial>
      <collision name='leg2a1_collision'>
        <pose frame=''>0 0 0 0 -0 0</pose>
        <geometry>
          <mesh>
            <scale>1 1 1</scale>
            <uri>model://minitaur/meshes/leg2a1.STL</uri>
          </mesh>
        </geometry>
      </collision>
      <visual name='leg2a1_visual'>
        <pose frame=''>0 0 0 0 -0 0</pose>
        <geometry>
          <mesh>
            <scale>1 1 1</scale>
            <uri>model://minitaur/meshes/leg2a1.STL</uri>
          </mesh>
        </geometry>
      </visual>
    </link>
    <joint name='leg2j1' type='revolute'>
      <child>leg2a1</child>
      <parent>base_link</parent>
      <axis>
        <xyz>0 -1 4e-06</xyz>
        <limit>
          <lower>-1e+16</lower>
          <upper>1e+16</upper>
        </limit>
        <dynamics>
          <spring_reference>0</spring_reference>
          <spring_stiffness>0</spring_stiffness>
        </dynamics>
        <use_parent_model_frame>1</use_parent_model_frame>
      </axis>
    </joint>
    <link name='leg2a2'>
      <pose frame=''>0.068033 -0.071332 0.10916 -1.5708 -0.89566 5e-06</pose>
      <inertial>
        <pose frame=''>-0.053394 -0 -0.002796 0 -0 0</pose>
        <mass>0.016662</mass>
        <inertia>
          <ixx>6.06e-07</ixx>
          <ixy>0</ixy>
          <ixz>-1.58e-07</ixz>
          <iyy>1.85e-05</iyy>
          <iyz>0</iyz>
          <izz>1.9e-05</izz>
        </inertia>
      </inertial>
      <collision name='leg2a2_collision'>
        <pose frame=''>0 0 0 0 -0 0</pose>
        <geometry>
          <mesh>
            <scale>1 1 1</scale>
            <uri>model://minitaur/meshes/leg2a2.STL</uri>
          </mesh>
        </geometry>
      </collision>
      <visual name='leg2a2_visual'>
        <pose frame=''>0 0 0 0 -0 0</pose>
        <geometry>
          <mesh>
            <scale>1 1 1</scale>
            <uri>model://minitaur/meshes/leg2a2.STL</uri>
          </mesh>
        </geometry>
      </visual>
    </link>
    <joint name='leg2j2' type='revolute'>
      <child>leg2a2</child>
      <parent>leg2a1</parent>
      <axis>
        <xyz>0 -1 4e-06</xyz>
        <limit>
          <lower>-1e+16</lower>
          <upper>1e+16</upper>
        </limit>
        <dynamics>
          <spring_reference>0</spring_reference>
          <spring_stiffness>0</spring_stiffness>
        </dynamics>
        <use_parent_model_frame>1</use_parent_model_frame>
      </axis>
    </joint>
    <link name='leg2a3'>
      <pose frame=''>-0.006967 -0.065332 0.10916 1.5708 0 3.14159</pose>
      <inertial>
        <pose frame=''>0.027399 0 -0.008649 0 -0 0</pose>
        <mass>0.0096655</mass>
        <inertia>
          <ixx>3.47e-07</ixx>
          <ixy>0</ixy>
          <ixz>7.67e-08</ixz>
          <iyy>3.57e-06</iyy>
          <iyz>0</iyz>
          <izz>3.82e-06</izz>
        </inertia>
      </inertial>
      <collision name='leg2a3_collision'>
        <pose frame=''>0 0 0 0 -0 0</pose>
        <geometry>
          <mesh>
            <scale>1 1 1</scale>
            <uri>model://minitaur/meshes/leg2a3.STL</uri>
          </mesh>
        </geometry>
      </collision>
      <visual name='leg2a3_visual'>
        <pose frame=''>0 0 0 0 -0 0</pose>
        <geometry>
          <mesh>
            <scale>1 1 1</scale>
            <uri>model://minitaur/meshes/leg2a3.STL</uri>
          </mesh>
        </geometry>
      </visual>
    </link>
    <joint name='leg2j3' type='revolute'>
      <child>leg2a3</child>
      <parent>base_link</parent>
      <axis>
        <xyz>-7e-06 -1 4e-06</xyz>
        <limit>
          <lower>-1e+16</lower>
          <upper>1e+16</upper>
        </limit>
        <dynamics>
          <spring_reference>0</spring_reference>
          <spring_stiffness>0</spring_stiffness>
        </dynamics>
        <use_parent_model_frame>1</use_parent_model_frame>
      </axis>
    </joint>
    <link name='leg2a4'>
      <pose frame=''>-0.056967 -0.065332 0.10916 -1.57078 -0.89566 3.14158</pose>
      <inertial>
        <pose frame=''>-0.05 -0 0.003 0 -0 0</pose>
        <mass>0.015531</mass>
        <inertia>
          <ixx>5.76e-07</ixx>
          <ixy>0</ixy>
          <ixz>0</ixz>
          <iyy>1.59e-05</iyy>
          <iyz>0</iyz>
          <izz>1.64e-05</izz>
        </inertia>
      </inertial>
      <collision name='leg2a4_collision'>
        <pose frame=''>0 0 0 0 -0 0</pose>
        <geometry>
          <mesh>
            <scale>1 1 1</scale>
            <uri>model://minitaur/meshes/leg2a4.STL</uri>
          </mesh>
        </geometry>
      </collision>
      <visual name='leg2a4_visual'>
        <pose frame=''>0 0 0 0 -0 0</pose>
        <geometry>
          <mesh>
            <scale>1 1 1</scale>
            <uri>model://minitaur/meshes/leg2a4.STL</uri>
          </mesh>
        </geometry>
      </visual>
    </link>
    <joint name='leg2j4' type='revolute'>
      <child>leg2a4</child>
      <parent>leg2a3</parent>
      <axis>
        <xyz>-2e-06 -1 8e-06</xyz>
        <limit>
          <lower>-1e+16</lower>
          <upper>1e+16</upper>
        </limit>
        <dynamics>
          <spring_reference>0</spring_reference>
          <spring_stiffness>0</spring_stiffness>
        </dynamics>
        <use_parent_model_frame>1</use_parent_model_frame>
      </axis>
    </joint>
    <link name='leg3a1'>
      <pose frame=''>0.14803 -0.22533 0.10916 -1.5708 0 -3.14159</pose>
      <inertial>
        <pose frame=''>0.027399 0 0.003351 0 -0 0</pose>
        <mass>0.0096655</mass>
        <inertia>
          <ixx>3.47e-07</ixx>
          <ixy>0</ixy>
          <ixz>7.67e-08</ixz>
          <iyy>3.57e-06</iyy>
          <iyz>0</iyz>
          <izz>3.82e-06</izz>
        </inertia>
      </inertial>
      <collision name='leg3a1_collision'>
        <pose frame=''>0 0 0 0 -0 0</pose>
        <geometry>
          <mesh>
            <scale>1 1 1</scale>
            <uri>model://minitaur/meshes/leg3a1.STL</uri>
          </mesh>
        </geometry>
      </collision>
      <visual name='leg3a1_visual'>
        <pose frame=''>0 0 0 0 -0 0</pose>
        <geometry>
          <mesh>
            <scale>1 1 1</scale>
            <uri>model://minitaur/meshes/leg3a1.STL</uri>
          </mesh>
        </geometry>
      </visual>
    </link>
    <joint name='leg3j1' type='revolute'>
      <child>leg3a1</child>
      <parent>base_link</parent>
      <axis>
        <xyz>7e-06 -1 -4e-06</xyz>
        <limit>
          <lower>-1e+16</lower>
          <upper>1e+16</upper>
        </limit>
        <dynamics>
          <spring_reference>0</spring_reference>
          <spring_stiffness>0</spring_stiffness>
        </dynamics>
        <use_parent_model_frame>1</use_parent_model_frame>
      </axis>
    </joint>
    <link name='leg3a2'>
      <pose frame=''>0.09803 -0.23133 0.10916 -1.5708 -0.89566 -3.14158</pose>
      <inertial>
        <pose frame=''>-0.053394 0 0.003204 0 -0 0</pose>
        <mass>0.016662</mass>
        <inertia>
          <ixx>6.06e-07</ixx>
          <ixy>0</ixy>
          <ixz>-1.58e-07</ixz>
          <iyy>1.85e-05</iyy>
          <iyz>0</iyz>
          <izz>1.9e-05</izz>
        </inertia>
      </inertial>
      <collision name='leg3a2_collision'>
        <pose frame=''>0 0 0 0 -0 0</pose>
        <geometry>
          <mesh>
            <scale>1 1 1</scale>
            <uri>model://minitaur/meshes/leg3a2.STL</uri>
          </mesh>
        </geometry>
      </collision>
      <visual name='leg3a2_visual'>
        <pose frame=''>0 0 0 0 -0 0</pose>
        <geometry>
          <mesh>
            <scale>1 1 1</scale>
            <uri>model://minitaur/meshes/leg3a2.STL</uri>
          </mesh>
        </geometry>
      </visual>
    </link>
    <joint name='leg3j2' type='revolute'>
      <child>leg3a2</child>
      <parent>leg3a1</parent>
      <axis>
        <xyz>7e-06 -1 -4e-06</xyz>
        <limit>
          <lower>-1e+16</lower>
          <upper>1e+16</upper>
        </limit>
        <dynamics>
          <spring_reference>0</spring_reference>
          <spring_stiffness>0</spring_stiffness>
        </dynamics>
        <use_parent_model_frame>1</use_parent_model_frame>
      </axis>
    </joint>
    <link name='leg3a3'>
      <pose frame=''>0.17303 -0.23133 0.10916 1.5708 -0 0</pose>
      <inertial>
        <pose frame=''>0.027399 0 0.003351 0 -0 0</pose>
        <mass>0.0096655</mass>
        <inertia>
          <ixx>3.47e-07</ixx>
          <ixy>0</ixy>
          <ixz>7.67e-08</ixz>
          <iyy>3.57e-06</iyy>
          <iyz>0</iyz>
          <izz>3.82e-06</izz>
        </inertia>
      </inertial>
      <collision name='leg3a3_collision'>
        <pose frame=''>0 0 0 0 -0 0</pose>
        <geometry>
          <mesh>
            <scale>1 1 1</scale>
            <uri>model://minitaur/meshes/leg3a3.STL</uri>
          </mesh>
        </geometry>
      </collision>
      <visual name='leg3a3_visual'>
        <pose frame=''>0 0 0 0 -0 0</pose>
        <geometry>
          <mesh>
            <scale>1 1 1</scale>
            <uri>model://minitaur/meshes/leg3a3.STL</uri>
          </mesh>
        </geometry>
      </visual>
    </link>
    <joint name='leg3j3' type='revolute'>
      <child>leg3a3</child>
      <parent>base_link</parent>
      <axis>
        <xyz>0 -1 -4e-06</xyz>
        <limit>
          <lower>-1e+16</lower>
          <upper>1e+16</upper>
        </limit>
        <dynamics>
          <spring_reference>0</spring_reference>
          <spring_stiffness>0</spring_stiffness>
        </dynamics>
        <use_parent_model_frame>1</use_parent_model_frame>
      </axis>
    </joint>
    <link name='leg3a4'>
      <pose frame=''>0.22303 -0.23733 0.10916 -1.5708 0.895693 3.14159</pose>
      <inertial>
        <pose frame=''>0.05 0 0.003 0 -0 0</pose>
        <mass>0.015531</mass>
        <inertia>
          <ixx>5.76e-07</ixx>
          <ixy>0</ixy>
          <ixz>0</ixz>
          <iyy>1.59e-05</iyy>
          <iyz>0</iyz>
          <izz>1.64e-05</izz>
        </inertia>
      </inertial>
      <collision name='leg3a4_collision'>
        <pose frame=''>0 0 0 0 -0 0</pose>
        <geometry>
          <mesh>
            <scale>1 1 1</scale>
            <uri>model://minitaur/meshes/leg3a4.STL</uri>
          </mesh>
        </geometry>
      </collision>
      <visual name='leg3a4_visual'>
        <pose frame=''>0 0 0 0 -0 0</pose>
        <geometry>
          <mesh>
            <scale>1 1 1</scale>
            <uri>model://minitaur/meshes/leg3a4.STL</uri>
          </mesh>
        </geometry>
      </visual>
    </link>
    <joint name='leg3j4' type='revolute'>
      <child>leg3a4</child>
      <parent>leg3a3</parent>
      <axis>
        <xyz>0 -1 -4e-06</xyz>
        <limit>
          <lower>-1e+16</lower>
          <upper>1e+16</upper>
        </limit>
        <dynamics>
          <spring_reference>0</spring_reference>
          <spring_stiffness>0</spring_stiffness>
        </dynamics>
        <use_parent_model_frame>1</use_parent_model_frame>
      </axis>
    </joint>
    <link name='leg4a1'>
      <pose frame=''>-0.006967 -0.22533 0.10916 -1.5708 -0 -3.14159</pose>
      <inertial>
        <pose frame=''>0.027399 0 0.003351 0 -0 0</pose>
        <mass>0.0096655</mass>
        <inertia>
          <ixx>3.47e-07</ixx>
          <ixy>0</ixy>
          <ixz>7.67e-08</ixz>
          <iyy>3.57e-06</iyy>
          <iyz>0</iyz>
          <izz>3.82e-06</izz>
        </inertia>
      </inertial>
      <collision name='leg4a1_collision'>
        <pose frame=''>0 0 0 0 -0 0</pose>
        <geometry>
          <mesh>
            <scale>1 1 1</scale>
            <uri>model://minitaur/meshes/leg4a1.STL</uri>
          </mesh>
        </geometry>
      </collision>
      <visual name='leg4a1_visual'>
        <pose frame=''>0 0 0 0 -0 0</pose>
        <geometry>
          <mesh>
            <scale>1 1 1</scale>
            <uri>model://minitaur/meshes/leg4a1.STL</uri>
          </mesh>
        </geometry>
      </visual>
    </link>
    <joint name='leg4j1' type='revolute'>
      <child>leg4a1</child>
      <parent>base_link</parent>
      <axis>
        <xyz>7e-06 -1 -4e-06</xyz>
        <limit>
          <lower>-1e+16</lower>
          <upper>1e+16</upper>
        </limit>
        <dynamics>
          <spring_reference>0</spring_reference>
          <spring_stiffness>0</spring_stiffness>
        </dynamics>
        <use_parent_model_frame>1</use_parent_model_frame>
      </axis>
    </joint>
    <link name='leg4a2'>
      <pose frame=''>-0.056967 -0.23133 0.10916 -1.5708 -0.89566 -3.14158</pose>
      <inertial>
        <pose frame=''>-0.053394 -0 0.003204 0 -0 0</pose>
        <mass>0.016662</mass>
        <inertia>
          <ixx>6.06e-07</ixx>
          <ixy>0</ixy>
          <ixz>-1.58e-07</ixz>
          <iyy>1.85e-05</iyy>
          <iyz>0</iyz>
          <izz>1.9e-05</izz>
        </inertia>
      </inertial>
      <collision name='leg4a2_collision'>
        <pose frame=''>0 0 0 0 -0 0</pose>
        <geometry>
          <mesh>
            <scale>1 1 1</scale>
            <uri>model://minitaur/meshes/leg4a2.STL</uri>
          </mesh>
        </geometry>
      </collision>
      <visual name='leg4a2_visual'>
        <pose frame=''>0 0 0 0 -0 0</pose>
        <geometry>
          <mesh>
            <scale>1 1 1</scale>
            <uri>model://minitaur/meshes/leg4a2.STL</uri>
          </mesh>
        </geometry>
      </visual>
    </link>
    <joint name='leg4j2' type='revolute'>
      <child>leg4a2</child>
      <parent>leg4a1</parent>
      <axis>
        <xyz>7e-06 -1 -4e-06</xyz>
        <limit>
          <lower>-1e+16</lower>
          <upper>1e+16</upper>
        </limit>
        <dynamics>
          <spring_reference>0</spring_reference>
          <spring_stiffness>0</spring_stiffness>
        </dynamics>
        <use_parent_model_frame>1</use_parent_model_frame>
      </axis>
    </joint>
    <link name='leg4a3'>
      <pose frame=''>0.018033 -0.23133 0.10916 1.5708 -0 0</pose>
      <inertial>
        <pose frame=''>0.027399 0 0.003351 0 -0 0</pose>
        <mass>0.0096655</mass>
        <inertia>
          <ixx>3.47e-07</ixx>
          <ixy>0</ixy>
          <ixz>7.67e-08</ixz>
          <iyy>3.57e-06</iyy>
          <iyz>0</iyz>
          <izz>3.82e-06</izz>
        </inertia>
      </inertial>
      <collision name='leg4a3_collision'>
        <pose frame=''>0 0 0 0 -0 0</pose>
        <geometry>
          <mesh>
            <scale>1 1 1</scale>
            <uri>model://minitaur/meshes/leg4a3.STL</uri>
          </mesh>
        </geometry>
      </collision>
      <visual name='leg4a3_visual'>
        <pose frame=''>0 0 0 0 -0 0</pose>
        <geometry>
          <mesh>
            <scale>1 1 1</scale>
            <uri>model://minitaur/meshes/leg4a3.STL</uri>
          </mesh>
        </geometry>
      </visual>
    </link>
    <joint name='leg4j3' type='revolute'>
      <child>leg4a3</child>
      <parent>base_link</parent>
      <axis>
        <xyz>0 -1 -4e-06</xyz>
        <limit>
          <lower>-1e+16</lower>
          <upper>1e+16</upper>
        </limit>
        <dynamics>
          <spring_reference>0</spring_reference>
          <spring_stiffness>0</spring_stiffness>
        </dynamics>
        <use_parent_model_frame>1</use_parent_model_frame>
      </axis>
    </joint>
    <link name='leg4a4'>
      <pose frame=''>0.068033 -0.23733 0.10916 -1.5708 0.895693 3.14159</pose>
      <inertial>
        <pose frame=''>0.05 0 0.003 0 -0 0</pose>
        <mass>0.015531</mass>
        <inertia>
          <ixx>5.76e-07</ixx>
          <ixy>0</ixy>
          <ixz>0</ixz>
          <iyy>1.59e-05</iyy>
          <iyz>0</iyz>
          <izz>1.64e-05</izz>
        </inertia>
      </inertial>
      <collision name='leg4a4_collision'>
        <pose frame=''>0 0 0 0 -0 0</pose>
        <geometry>
          <mesh>
            <scale>1 1 1</scale>
            <uri>model://minitaur/meshes/leg4a4.STL</uri>
          </mesh>
        </geometry>
      </collision>
      <visual name='leg4a4_visual'>
        <pose frame=''>0 0 0 0 -0 0</pose>
        <geometry>
          <mesh>
            <scale>1 1 1</scale>
            <uri>model://minitaur/meshes/leg4a4.STL</uri>
          </mesh>
        </geometry>
      </visual>
    </link>
    <joint name='leg4j4' type='revolute'>
      <child>leg4a4</child>
      <parent>leg4a3</parent>
      <axis>
        <xyz>0 -1 -4e-06</xyz>
        <limit>
          <lower>-1e+16</lower>
          <upper>1e+16</upper>
        </limit>
        <dynamics>
          <spring_reference>0</spring_reference>
          <spring_stiffness>0</spring_stiffness>
        </dynamics>
        <use_parent_model_frame>1</use_parent_model_frame>
      </axis>
    </joint>
  </model>
</sdf>
